Workbook

Sheet README
A1: Quillmere Systems, Inc. — FY2026 FP&A Dataset
A2: DISCLAIMER | B2: For learning purposes only. Quillmere Systems is a fictional company. All people, customers, vendors, transactions, financial figures and events in this workbook were invented for training. If any name matches a real company or person, that is coincidental and nothing here describes a real transaction, relationship or price. Not financial, investment or accounting advice.
A3: Company | B3: Quillmere Systems builds supply-chain visibility software for mid-market distributors, grocers and manufacturers. HQ: Philadelphia. ~460 employees. Fiscal year = calendar year.
A4: Business model | B4: Annual SaaS subscriptions billed upfront and recognized ratably, plus implementation / professional services billed on milestones.
A5: Scale | B5: Opening FY26 ARR $108.0M; FY26 Operating Plan targets $128.0M exit ARR and ~$121M revenue.
A6: Status | B6: Books closed through Sep 2026. Oct–Dec are budget only.
A8: Tab | B8: What it is
A9: GL_Actuals | B9: Closed monthly actuals by department and GL account (long format — pivot it). Amounts are positive for both revenue and expense.
A10: Budget | B10: FY2026 Operating Plan, board-approved Dec 2025. Same structure as GL_Actuals, all 12 months.
A11: GL_Detail_Sep | B11: September journal-entry detail with vendor and description. Use it to explain variances.
A12: Headcount | B12: Employee roster + FY26 open reqs. Planned_Start is when the plan assumed a req would be filled.
A13: ARR_Drivers | B13: Monthly ARR bridge (open, new+expansion, churn, close) — Budget vs Actual.
A14: PY_Summary | B14: FY2025 actuals at summary P&L level for year-over-year context.
... A17: Sign convention | B17: All amounts positive. Variance convention at Quillmere: Favorable = revenue above budget or expense below budget.

Sheet GL_Actuals
A1: Period | B1: Department | C1: Account | D1: Account Name | E1: P&L Rollup | F1: Amount
A2: 2026-01 | B2: Revenue | C2: 4000 | D2: Subscription Revenue | E2: Revenue | F2: 9013095.9
A3: 2026-01 | B3: Revenue | C3: 4100 | D3: Professional Services Revenue | E3: Revenue | F3: 679000
A4: 2026-01 | B4: Cost of Revenue | C4: 5000 | D4: Hosting & Infrastructure | E4: Cost of Revenue | F4: 886234.69
A5: 2026-01 | B5: Cost of Revenue | C5: 5300 | D5: Third-Party Software Licenses | E5: Cost of Revenue | F5: 166197.89
A6: 2026-01 | B6: Sales | C6: 6000 | D6: Salaries & Wages | E6: Sales & Marketing | F6: 761238.56
A7: 2026-01 | B7: Sales | C7: 6010 | D7: Payroll Taxes & Benefits | E7: Sales & Marketing | F7: 186546.44
A8: 2026-01 | B8: Sales | C8: 6200 | D8: Software & Subscriptions | E8: Sales & Marketing | F8: 23153.45
A9: 2026-01 | B9: Sales | C9: 6300 | D9: Travel & Entertainment | E9: Sales & Marketing | F9: 69158.42
A10: 2026-01 | B10: Sales | C10: 6800 | D10: Recruiting | E10: Sales & Marketing | F10: 18272.84
A11: 2026-01 | B11: Marketing | C11: 6000 | D11: Salaries & Wages | E11: Sales & Marketing | F11: 258326.09
A12: 2026-01 | B12: Marketing | C12: 6010 | D12: Payroll Taxes & Benefits | E12: Sales & Marketing | F12: 62903.82
A13: 2026-01 | B13: Marketing | C13: 6200 | D13: Software & Subscriptions | E13: Sales & Marketing | F13: 7181.57
... A433: 2026-09 | B433: G&A | C433: 6700 | D433: Depreciation & Amortization | E433: General & Administrative | F433: 151500

Sheet Budget
A1: Period | B1: Department | C1: Account | D1: Account Name | E1: P&L Rollup | F1: Amount
A2: 2026-01 | B2: Revenue | C2: 4000 | D2: Subscription Revenue | E2: Revenue | F2: 9013320
A3: 2026-01 | B3: Revenue | C3: 4100 | D3: Professional Services Revenue | E3: Revenue | F3: 700000
A4: 2026-01 | B4: Cost of Revenue | C4: 5000 | D4: Hosting & Infrastructure | E4: Cost of Revenue | F4: 856265.4
A5: 2026-01 | B5: Cost of Revenue | C5: 5300 | D5: Third-Party Software Licenses | E5: Cost of Revenue | F5: 167000
A6: 2026-01 | B6: Sales | C6: 6000 | D6: Salaries & Wages | E6: Sales & Marketing | F6: 763833.33
A7: 2026-01 | B7: Sales | C7: 6010 | D7: Payroll Taxes & Benefits | E7: Sales & Marketing | F7: 187139.17
A8: 2026-01 | B8: Sales | C8: 6200 | D8: Software & Subscriptions | E8: Sales & Marketing | F8: 24180
A9: 2026-01 | B9: Sales | C9: 6300 | D9: Travel & Entertainment | E9: Sales & Marketing | F9: 57660
A10: 2026-01 | B10: Sales | C10: 6800 | D10: Recruiting | E10: Sales & Marketing | F10: 17500
A11: 2026-01 | B11: Marketing | C11: 6000 | D11: Salaries & Wages | E11: Sales & Marketing | F11: 268541.67
A12: 2026-01 | B12: Marketing | C12: 6010 | D12: Payroll Taxes & Benefits | E12: Sales & Marketing | F12: 65792.71
A13: 2026-01 | B13: Marketing | C13: 6200 | D13: Software & Subscriptions | E13: Sales & Marketing | F13: 7540
... A577: 2026-12 | B577: G&A | C577: 6700 | D577: Depreciation & Amortization | E577: General & Administrative | F577: 156000

Sheet GL_Detail_Sep
A1: JE # | B1: Date | C1: Account | D1: Account Name | E1: Department | F1: Vendor / Customer | G1: Description | H1: Amount
A2: JE-SEP-4101 | B2: 2026-09-30 | C2: 4000 | D2: Subscription Revenue | E2: Revenue | F2: Orion Grocers | G2: Subscription revenue – ratable recognition | H2: 3055.56
A3: JE-SEP-4102 | B3: 2026-09-30 | C3: 4000 | D3: Subscription Revenue | E3: Revenue | F3: Pinecrest Health | G3: Subscription revenue – ratable recognition | H3: 82276.58
A4: JE-SEP-4103 | B4: 2026-09-30 | C4: 4000 | D4: Subscription Revenue | E4: Revenue | F4: Atlas Manufacturing | G4: Subscription revenue – ratable recognition | H4: 84740.6
A5: JE-SEP-4104 | B5: 2026-09-30 | C5: 4000 | D5: Subscription Revenue | E5: Revenue | F5: Keystone Mutual | G5: Subscription revenue – ratable recognition | H5: 134632.07
A6: JE-SEP-4105 | B6: 2026-09-30 | C6: 4000 | D6: Subscription Revenue | E6: Revenue | F6: Bramblewood Foods | G6: Subscription revenue – ratable recognition | H6: 96766.71
A7: JE-SEP-4106 | B7: 2026-09-30 | C7: 4000 | D7: Subscription Revenue | E7: Revenue | F7: Tidewater Ports | G7: Subscription revenue – ratable recognition | H7: 129273.14
A8: JE-SEP-4107 | B8: 2026-09-30 | C8: 4000 | D8: Subscription Revenue | E8: Revenue | F8: Sterling Freightways | G8: Subscription revenue – ratable recognition | H8: 141774.92
A9: JE-SEP-4108 | B9: 2026-09-30 | C9: 4000 | D9: Subscription Revenue | E9: Revenue | F9: Calder Biotech | G9: Subscription revenue – ratable recognition | H9: 85645.4
A10: JE-SEP-4109 | B10: 2026-09-30 | C10: 4000 | D10: Subscription Revenue | E10: Revenue | F10: Northgate Retail | G10: Subscription revenue – ratable recognition | H10: 150995.94
A11: JE-SEP-4110 | B11: 2026-09-30 | C11: 4000 | D11: Subscription Revenue | E11: Revenue | F11: Ambergrid Utilities | G11: Subscription revenue – ratable recognition | H11: 133505.72
A12: JE-SEP-4111 | B12: 2026-09-30 | C12: 4000 | D12: Subscription Revenue | E12: Revenue | F12: Redfield Logistics | G12: Subscription revenue – ratable recognition | H12: 102723.05
A13: JE-SEP-4112 | B13: 2026-09-30 | C13: 4000 | D13: Subscription Revenue | E13: Revenue | F13: Ashby Pharma | G13: Subscription revenue – ratable recognition | H13: 101079.16
... A89: JE-SEP-4174 | B89: 2026-09-28 | C89: 6800 | D89: Recruiting | E89: Professional Services | F89: ProNet / Reqtrail | G89: Job postings & ATS | H89: 4062.08

Sheet Headcount
A1: Employee ID | B1: Name | C1: Req ID | D1: Department | E1: Title | F1: Level | G1: Annual Base Salary | H1: Status | I1: Start Date | J1: Term Date | K1: Planned_Start (Budget)
A2: E1001 | B2: Remy Nguyen | D2: Sales | E2: Account Executive | F2: IC2 | G2: 81000 | H2: Terminated | I2: 2022-09-15 | J2: 2026-03-15
A3: E1002 | B3: Lane Fischer | D3: Sales | E3: Sales Engineer | F3: IC3 | G3: 108500 | H3: Active | I3: 2019-12-15
A4: E1003 | B4: Dakota Kowalski | D4: Sales | E4: Sales Engineer | F4: Mgr | G4: 132500 | H4: Active | I4: 2024-04-01
A5: E1004 | B5: Drew Silva | D5: Sales | E5: Sales Development Rep | F5: IC1 | G5: 70500 | H5: Active | I5: 2022-05-01
A6: E1005 | B6: Noel Dubois | D6: Sales | E6: Sr. Account Executive | F6: IC3 | G6: 97000 | H6: Active | I6: 2025-04-01
A7: E1006 | B7: Corin Nguyen | D7: Sales | E7: Account Executive | F7: IC2 | G7: 84000 | H7: Active | I7: 2024-10-15
A8: E1007 | B8: Casey Abbott | D8: Sales | E8: Sr. Account Executive | F8: IC4 | G8: 123000 | H8: Active | I8: 2024-02-01
A9: E1008 | B9: Wren Kowalski | D9: Sales | E9: Sales Development Rep | F9: IC1 | G9: 67500 | H9: Active | I9: 2025-09-01
A10: E1009 | B10: Finley Brennan | D10: Sales | E10: Sales Development Rep | F10: IC1 | G10: 68000 | H10: Active | I10: 2022-05-15
A11: E1010 | B11: Lane Haddad | D11: Sales | E11: Sr. Account Executive | F11: Mgr | G11: 124000 | H11: Active | I11: 2018-05-01
A12: E1011 | B12: Briar Fischer | D12: Sales | E12: Sales Development Rep | F12: IC3 | G12: 113000 | H12: Active | I12: 2022-06-15
A13: E1012 | B13: Kai Okafor | D13: Sales | E13: Sales Development Rep | F13: Mgr | G13: 141000 | H13: Active | I13: 2018-10-01
A14: E1013 | B14: Corin Novak | D14: Sales | E14: Sales Engineer | F14: IC1 | G14: 76000 | H14: Active | I14: 2022-06-01
... A55: E1054 | B55: Jesse Yilmaz | D55: Sales | E55: Sr. Account Executive | F55: IC1 | G55: 68500 | H55: Active | I55: 2023-08-15
A56: E1055 | B56: Tatum Moreau | D56: Sales | E56: Sales Manager | F56: IC2 | G56: 93500 | H56: Terminated | I56: 2022-01-01 | J56: 2026-07-15
A57: E1056 | B57: Marley Larsen | D57: Sales | E57: Sales Manager | F57: IC1 | G57: 78500 | H57: Active | I57: 2022-05-15
A58: E1057 | B58: Hayden Romero | D58: Sales | E58: Sales Development Rep | F58: IC1 | G58: 79000 | H58: Active | I58: 2022-12-01
A59: E1058 | B59: Taylor Mensah | D59: Sales | E59: Sr. Account Executive | F59: IC2 | G59: 84000 | H59: Active | I59: 2025-10-15
A60: E1059 | B60: Hayden Okafor | D60: Sales | E60: Sales Engineer | F60: IC2 | G60: 96000 | H60: Active | I60: 2021-10-15
A61: E1060 | B61: Elliot Castillo | D61: Sales | E61: Sales Manager | F61: IC2 | G61: 93000 | H61: Active | I61: 2024-01-01
A62: E1061 | B62: Oakley Walsh | D62: Sales | E62: Sales Development Rep | F62: IC1 | G62: 77000 | H62: Active | I62: 2020-03-15
A63: E1062 | B63: Drew Garcia | D63: Sales | E63: Account Executive | F63: IC2 | G63: 81500 | H63: Active | I63: 2024-05-01
A64: E1063 | B64: Sawyer Sato | D64: Sales | E64: Sales Manager | F64: IC4 | G64: 117500 | H64: Active | I64: 2021-08-01
A65: E1064 | B65: Finley Rossi | D65: Sales | E65: Sales Engineer | F65: IC1 | G65: 71500 | H65: Active | I65: 2018-07-15
A66: E1065 | B66: Remy Novak | D66: Sales | E66: Sales Manager | F66: Mgr | G66: 124500 | H66: Active | I66: 2021-03-15
A67: E1066 | B67: Logan Kim | D67: Sales | E67: Sales Engineer | F67: IC2 | G67: 87500 | H67: Active | I67: 2025-12-01
A68: E1067 | B68: Reese Brennan | D68: Sales | E68: Sales Development Rep | F68: IC4 | G68: 113000 | H68: Active | I68: 2025-09-01
... A104: E1103 | B104: Sawyer Zhang | D104: Marketing | E104: Demand Gen Specialist | F104: IC1 | G104: 85000 | H104: Active | I104: 2020-03-15
A105: E1104 | B105: Noel Novak | D105: Marketing | E105: Product Marketing Manager | F105: IC1 | G105: 90500 | H105: Terminated | I105: 2020-02-15 | J105: 2026-06-15
A106: E1105 | B106: Jordan Chen | D106: Marketing | E106: Demand Gen Specialist | F106: IC1 | G106: 86000 | H106: Active | I106: 2022-11-01
A107: E1106 | B107: Dakota Moreau | D107: Marketing | E107: Product Marketing Manager | F107: IC2 | G107: 98500 | H107: Active | I107: 2020-05-15
A108: E1107 | B108: Skyler Patel | D108: Marketing | E108: Product Marketing Manager | F108: IC2 | G108: 93000 | H108: Active | I108: 2021-04-01
A109: E1108 | B109: Reese Nguyen | D109: Marketing | E109: Demand Gen Specialist | F109: IC3 | G109: 126000 | H109: Active | I109: 2025-01-01
A110: E1109 | B110: Quinn Castillo | D110: Marketing | E110: Product Marketing Manager | F110: IC4 | G110: 148500 | H110: Active | I110: 2020-06-01
A111: E1110 | B111: Hayden Yilmaz | D111: Marketing | E111: Marketing Manager | F111: IC1 | G111: 80500 | H111: Active | I111: 2019-09-15
A112: E1111 | B112: Riley Abbott | D112: Marketing | E112: Marketing Manager | F112: IC2 | G112: 101500 | H112: Active | I112: 2020-06-15
A113: E1112 | B113: Reese Haddad | D113: Marketing | E113: Marketing Manager | F113: IC1 | G113: 85000 | H113: Active | I113: 2022-02-01
A114: E1113 | B114: Sawyer Okafor | D114: Marketing | E114: Demand Gen Specialist | F114: IC1 | G114: 88500 | H114: Active | I114: 2022-11-01
A115: E1114 | B115: Hayden Dubois | D115: Marketing | E115: Content Strategist | F115: IC1 | G115: 88000 | H115: Active | I115: 2019-03-15
...

Sheet ARR_Drivers
A1: Period | B1: Bud Opening ARR | C1: Bud New+Expansion | D1: Bud Churn | E1: Bud Closing ARR | F1: Act Opening ARR | G1: Act New+Expansion | H1: Act Churn | I1: Act Closing ARR
A2: 2026-01 | B2: 108000000 | C2: 1219680 | D2: 450000 | E2: 108769680 | F2: 108000000 | G2: 1134302.4 | H2: 410000 | I2: 1.087243e+08
A3: 2026-02 | B3: 108769680 | C3: 1663200 | D3: 450000 | E3: 109982880 | F3: 1.087243e+08 | G3: 1746360 | H3: 470000 | I3: 1.1000066e+08
A4: 2026-03 | B4: 109982880 | C4: 2661120 | D4: 450000 | E4: 112194000 | F4: 1.1000066e+08 | G4: 2581286.4 | H4: 520000 | I4: 1.1206195e+08
A5: 2026-04 | B5: 112194000 | C5: 1393920 | D5: 450000 | E5: 113137920 | F5: 1.1206195e+08 | G5: 1449676.8 | H5: 430000 | I5: 1.1308163e+08
A6: 2026-05 | B6: 113137920 | C6: 1900800 | D6: 450000 | E6: 114588720 | F6: 1.1308163e+08 | G6: 1805760 | H6: 390000 | I6: 1.1449739e+08
A7: 2026-06 | B7: 114588720 | C7: 3041280 | D7: 450000 | E7: 117180000 | F7: 1.1449739e+08 | G7: 3102105.6 | H7: 480000 | I7: 1.1711949e+08
A8: 2026-07 | B8: 117180000 | C8: 1510080 | D8: 450000 | E8: 118240080 | F8: 1.1711949e+08 | G8: 1419475.2 | H8: 445000 | I8: 1.1809397e+08
A9: 2026-08 | B9: 118240080 | C9: 2059200 | D9: 450000 | E9: 119849280 | F9: 1.1809397e+08 | G9: 1997424 | H9: 460000 | I9: 1.1963139e+08
A10: 2026-09 | B10: 119849280 | C10: 3294720 | D10: 450000 | E10: 122694000 | F10: 1.1963139e+08 | G10: 4480819.2 | H10: 1710000 | I10: 1.2240221e+08
A11: 2026-10 | B11: 122694000 | C11: 1684320 | D11: 450000 | E11: 123928320
A12: 2026-11 | B12: 123928320 | C12: 2296800 | D12: 450000 | E12: 125775120
A13: 2026-12 | B13: 125775120 | C13: 3674880 | D13: 450000 | E13: 129000000
B15: Commission Rate
B16: =GL_Detail_Sep!H54/ARR_Drivers!G10 -> 0.11

Sheet PY_Summary
A1: Period | B1: Subscription Revenue | C1: Prof. Services Revenue | D1: Cost of Revenue | E1: Sales & Marketing | F1: Research & Development | G1: General & Administrative
A2: 2025-01 | B2: 7366061.5 | C2: 638926.42 | D2: 1692856 | E2: 3455695.5 | F2: 2107080 | G2: 1106872.6
A3: 2025-02 | B3: 7504494.7 | C3: 588698.86 | D3: 1659521 | E3: 3247121.2 | F3: 2051267.8 | G3: 1128192.1
A4: 2025-03 | B4: 7521337.5 | C4: 523514.1 | D4: 1601117.4 | E4: 3521196.3 | F4: 2092986.5 | G4: 1090733.2
A5: 2025-04 | B5: 7703791.4 | C5: 656874.33 | D5: 1740777 | E5: 3437433.1 | F5: 2145820.8 | G5: 1080139.9
A6: 2025-05 | B6: 7851757 | C6: 640905.59 | D6: 1739846.5 | E6: 3788007.3 | F6: 2219572.5 | G6: 1110207.5
A7: 2025-06 | B7: 7874202.1 | C7: 579885.4 | D7: 1685795.4 | E7: 3482288.3 | F7: 2185691.2 | G7: 1100843.1
A8: 2025-07 | B8: 8018096.1 | C8: 674329.02 | D8: 1786065.6 | E8: 3750987.2 | F8: 2210575.5 | G8: 1146208.7
A9: 2025-08 | B9: 8087927.4 | C9: 690881.09 | D9: 1807787.9 | E9: 3797096 | F9: 2294391.5 | G9: 1169532.7
A10: 2025-09 | B10: 8367025.9 | C10: 592806.84 | D10: 1743515.7 | E10: 3991347.6 | F10: 2247077.6 | G10: 1209328.4
A11: 2025-10 | B11: 8382307.3 | C11: 546085.88 | D11: 1701953.6 | E11: 4021582.8 | F11: 2294425.4 | G11: 1191100.1
A12: 2025-11 | B12: 8472193.4 | C12: 632166.31 | D12: 1789507 | E12: 3652553.8 | F12: 2304548.1 | G12: 1253871.3
A13: 2025-12 | B13: 8572107.2 | C13: 627798.27 | D13: 1794780.4 | E13: 3691386.1 | F13: 2348578.7 | G13: 1254560.5

Sheet Chart_of_Accounts
A1: Account | B1: Account Name | C1: P&L Rollup
A2: 4000 | B2: Subscription Revenue | C2: Revenue
A3: 4100 | B3: Professional Services Revenue | C3: Revenue
A4: 5000 | B4: Hosting & Infrastructure | C4: Cost of Revenue
A5: 5300 | B5: Third-Party Software Licenses | C5: Cost of Revenue
A6: 6000 | B6: Salaries & Wages | C6: By department: Customer Support & Professional Services → Cost of Revenue; Sales, Marketing, Customer Success → Sales & Marketing; R&D → Research & Development; G&A → General & Administrative
A7: 6010 | B7: Payroll Taxes & Benefits | C7: By department: Customer Support & Professional Services → Cost of Revenue; Sales, Marketing, Customer Success → Sales & Marketing; R&D → Research & Development; G&A → General & Administrative
A8: 6020 | B8: Sales Commissions | C8: By department: Customer Support & Professional Services → Cost of Revenue; Sales, Marketing, Customer Success → Sales & Marketing; R&D → Research & Development; G&A → General & Administrative
A9: 6100 | B9: Contractors | C9: By department: Customer Support & Professional Services → Cost of Revenue; Sales, Marketing, Customer Success → Sales & Marketing; R&D → Research & Development; G&A → General & Administrative
A10: 6200 | B10: Software & Subscriptions | C10: By department: Customer Support & Professional Services → Cost of Revenue; Sales, Marketing, Customer Success → Sales & Marketing; R&D → Research & Development; G&A → General & Administrative
A11: 6300 | B11: Travel & Entertainment | C11: By department: Customer Support & Professional Services → Cost of Revenue; Sales, Marketing, Customer Success → Sales & Marketing; R&D → Research & Development; G&A → General & Administrative
A12: 6400 | B12: Marketing Programs | C12: By department: Customer Support & Professional Services → Cost of Revenue; Sales, Marketing, Customer Success → Sales & Marketing; R&D → Research & Development; G&A → General & Administrative
A13: 6410 | B13: Events & Conferences | C13: By department: Customer Support & Professional Services → Cost of Revenue; Sales, Marketing, Customer Success → Sales & Marketing; R&D → Research & Development; G&A → General & Administrative
... A18: 6800 | B18: Recruiting | C18: By department: Customer Support & Professional Services → Cost of Revenue; Sales, Marketing, Customer Success → Sales & Marketing; R&D → Research & Development; G&A → General & Administrative

Sheet Summary
A1: Month | B1: 2026-09
B3: Line Item | C3: Sep Bud | D3: Sep Act | E3: $ Var | F3: % Var | G3: F/U | I3: YTD Bud | J3: YTD Act | K3: $ Var | L3: % Var | M3: F/U
B4: Subscription Revenue | C4: =SUMIFS(Budget!$F:$F,Budget!$D:$D,Summary!$B4,Budget!$A:$A,Summary!$B$1) -> 10087220 | D4: =SUMIFS(GL_Actuals!$F:$F,GL_Actuals!$D:$D,Summary!$B4,GL_Actuals!$A:$A,Summary!$B$1) -> 10013483 | E4: =D4-C4 -> -73736.67 | F4: =E4/C4 -> -0.00730991 | G4: =IF(E4>=0,"F","U") -> U | I4: =SUMIFS(Budget!$F:$F,Budget!$D:$D,Summary!$B4,Budget!$A:$A,"<="&$B$1) -> 85605380 | J4: =SUMIFS(GL_Actuals!$F:$F,GL_Actuals!$D:$D,Summary!$B4,GL_Actuals!$A:$A,"<="&$B$1) -> 85479531 | K4: =J4-I4 -> -125848.54 | L4: =K4/I4 -> -0.0014701008 | M4: =IF(K4>=0,"F","U") -> U
B5: Professional Services Revenue | C5: =SUMIFS(Budget!$F:$F,Budget!$D:$D,Summary!$B5,Budget!$A:$A,Summary!$B$1) -> 790000 | D5: =SUMIFS(GL_Actuals!$F:$F,GL_Actuals!$D:$D,Summary!$B5,GL_Actuals!$A:$A,Summary!$B$1) -> 561400 | E5: =D5-C5 -> -228600 | F5: =E5/C5 -> -0.28936709 | G5: =IF(E5>=0,"F","U") -> U | I5: =SUMIFS(Budget!$F:$F,Budget!$D:$D,Summary!$B5,Budget!$A:$A,"<="&$B$1) -> 6820000 | J5: =SUMIFS(GL_Actuals!$F:$F,GL_Actuals!$D:$D,Summary!$B5,GL_Actuals!$A:$A,"<="&$B$1) -> 6526300 | K5: =J5-I5 -> -293700 | L5: =K5/I5 -> -0.043064516 | M5: =IF(K5>=0,"F","U") -> U
B6: Total Revenue | C6: =SUM(C4:C5) -> 10877220 | D6: =SUM(D4:D5) -> 10574883 | E6: =D6-C6 -> -302336.67 | F6: =E6/C6 -> -0.027795399 | G6: =IF(E6>=0,"F","U") -> U | I6: =SUM(I4:I5) -> 92425380 | J6: =SUM(J4:J5) -> 92005831 | K6: =J6-I6 -> -419548.54 | L6: =K6/I6 -> -0.0045393218 | M6: =IF(K6>=0,"F","U") -> U
B7: Cost of Revenue | C7: =SUMIFS(Budget!$F:$F,Budget!$E:$E,Summary!$B7,Budget!$A:$A,Summary!$B$1) -> 1979694.4 | D7: =SUMIFS(GL_Actuals!$F:$F,GL_Actuals!$E:$E,Summary!$B7,GL_Actuals!$A:$A,Summary!$B$1) -> 2132628 | E7: =D7-C7 -> 152933.6 | F7: =E7/C7 -> 0.077251114 | G7: =IF(E7<=0,"F","U") -> U | I7: =SUMIFS(Budget!$F:$F,Budget!$E:$E,Summary!$B7,Budget!$A:$A,"<="&$B$1) -> 16998405 | J7: =SUMIFS(GL_Actuals!$F:$F,GL_Actuals!$E:$E,Summary!$B7,GL_Actuals!$A:$A,"<="&$B$1) -> 17401710 | K7: =J7-I7 -> 403305.3 | L7: =K7/I7 -> 0.023726068 | M7: =IF(K7<=0,"F","U") -> U
B8: Gross Profit | C8: =C6-C7 -> 8897525.6 | D8: =D6-D7 -> 8442255.3 | E8: =D8-C8 -> -455270.27 | F8: =E8/C8 -> -0.051168189 | G8: =IF(E8>=0,"F","U") -> U | I8: =I6-I7 -> 75426975 | J8: =J6-J7 -> 74604122 | K8: =J8-I8 -> -822853.84 | L8: =K8/I8 -> -0.010909278 | M8: =IF(K8>=0,"F","U") -> U
B9: Gross Margin % | C9: =C8/C6 -> 0.81799629 | D9: =D8/D6 -> 0.79833082 | E9: =D9-C9 -> -0.019665465 | F9: - | G9: =IF(E9>=0,"F","U") -> U | I9: =I8/I6 -> 0.8160851 | J9: =J8/J6 -> 0.81086297 | K9: =J9-I9 -> -0.0052221313 | L9: - | M9: =IF(K9>=0,"F","U") -> U
B10: Sales & Marketing | C10: =SUMIFS(Budget!$F:$F,Budget!$E:$E,Summary!$B10,Budget!$A:$A,Summary!$B$1) -> 3021337.5 | D10: =SUMIFS(GL_Actuals!$F:$F,GL_Actuals!$E:$E,Summary!$B10,GL_Actuals!$A:$A,Summary!$B$1) -> 3551319.2 | E10: =D10-C10 -> 529981.64 | F10: =E10/C10 -> 0.17541292 | G10: =IF(E10<=0,"F","U") -> U | I10: =SUMIFS(Budget!$F:$F,Budget!$E:$E,Summary!$B10,Budget!$A:$A,"<="&$B$1) -> 24692683 | J10: =SUMIFS(GL_Actuals!$F:$F,GL_Actuals!$E:$E,Summary!$B10,GL_Actuals!$A:$A,"<="&$B$1) -> 25059919 | K10: =J10-I10 -> 367236.17 | L10: =K10/I10 -> 0.014872267 | M10: =IF(K10<=0,"F","U") -> U
B11: Research & Development | C11: =SUMIFS(Budget!$F:$F,Budget!$E:$E,Summary!$B11,Budget!$A:$A,Summary!$B$1) -> 3089527.7 | D11: =SUMIFS(GL_Actuals!$F:$F,GL_Actuals!$E:$E,Summary!$B11,GL_Actuals!$A:$A,Summary!$B$1) -> 2949587.2 | E11: =D11-C11 -> -139940.48 | F11: =E11/C11 -> -0.045295104 | G11: =IF(E11<=0,"F","U") -> F | I11: =SUMIFS(Budget!$F:$F,Budget!$E:$E,Summary!$B11,Budget!$A:$A,"<="&$B$1) -> 26446149 | J11: =SUMIFS(GL_Actuals!$F:$F,GL_Actuals!$E:$E,Summary!$B11,GL_Actuals!$A:$A,"<="&$B$1) -> 25092400 | K11: =J11-I11 -> -1353748.8 | L11: =K11/I11 -> -0.051188883 | M11: =IF(K11<=0,"F","U") -> F
B12: General & Administrative | C12: =SUMIFS(Budget!$F:$F,Budget!$E:$E,Summary!$B12,Budget!$A:$A,Summary!$B$1) -> 1157665.6 | D12: =SUMIFS(GL_Actuals!$F:$F,GL_Actuals!$E:$E,Summary!$B12,GL_Actuals!$A:$A,Summary!$B$1) -> 1323057.7 | E12: =D12-C12 -> 165392.05 | F12: =E12/C12 -> 0.14286686 | G12: =IF(E12<=0,"F","U") -> U | I12: =SUMIFS(Budget!$F:$F,Budget!$E:$E,Summary!$B12,Budget!$A:$A,"<="&$B$1) -> 10436768 | J12: =SUMIFS(GL_Actuals!$F:$F,GL_Actuals!$E:$E,Summary!$B12,GL_Actuals!$A:$A,"<="&$B$1) -> 10562065 | K12: =J12-I12 -> 125297.35 | L12: =K12/I12 -> 0.012005378 | M12: =IF(K12<=0,"F","U") -> U
B13: Total OpEx | C13: =SUM(C10:C12) -> 7268530.9 | D13: =SUM(D10:D12) -> 7823964.1 | E13: =D13-C13 -> 555433.21 | F13: =E13/C13 -> 0.076416159 | G13: =IF(E13<=0,"F","U") -> U | I13: =SUM(I10:I12) -> 61575600 | J13: =SUM(J10:J12) -> 60714384 | K13: =J13-I13 -> -861215.31 | L13: =K13/I13 -> -0.013986308 | M13: =IF(K13<=0,"F","U") -> F
B14: Operating Income | C14: =C8-C13 -> 1628994.7 | D14: =D8-D13 -> 618291.22 | E14: =D14-C14 -> -1010703.5 | F14: =E14/C14 -> -0.62044614 | G14: =IF(E14>=0,"F","U") -> U | I14: =I8-I13 -> 13851376 | J14: =J8-J13 -> 13889737 | K14: =J14-I14 -> 38361.47 | L14: =K14/I14 -> 0.0027695061 | M14: =IF(K14>=0,"F","U") -> F
B15: Operating Margin % | C15: =C14/C6 -> 0.14976204 | D15: =D14/D6 -> 0.0584679 | E15: =D15-C15 -> -0.091294144 | F15: - | G15: =IF(E15>=0,"F","U") -> U | I15: =I14/I6 -> 0.1498655 | J15: =J14/J6 -> 0.15096584 | K15: =J15-I15 -> 0.0011003359 | L15: - | M15: =IF(K15>=0,"F","U") -> F
B17: Check | C17: =SUMIFS(GL_Actuals!$F:$F,GL_Actuals!$A:$A,Summary!$B$1)-(Summary!D6+Summary!D7+Summary!D13) -> 0
B19: Open question for Rachel
B20: README states a $128.0M exit ARR target; ARR_Drivers plans $129.0M December closing ARR. Which is the official target?

Sheet Dept_Detail
A1: Department | B1: Account | C1: Account Name | D1: Sep Bud | E1: Sep Act | F1: $ Var | G1: % Var | H1: F/U | I1: Material
A2: Revenue | B2: 4000 | C2: Subscription Revenue | D2: =SUMIFS(Budget!$F:$F,Budget!$A:$A,Summary!$B$1,Budget!$B:$B,Dept_Detail!$A2,Budget!$D:$D,Dept_Detail!$C2) -> 10087220 | E2: =SUMIFS(GL_Actuals!$F:$F,GL_Actuals!$A:$A,Summary!$B$1,GL_Actuals!$B:$B,$A2,GL_Actuals!$D:$D,Dept_Detail!$C2) -> 10013483 | F2: =E2-D2 -> -73736.67 | G2: =IFERROR(F2/D2,0) -> -0.00730991 | H2: =IF($A2="Revenue", IF(F2>=0,"F","U"),IF(F2<=0,"F","U")) -> U | I2: =AND(ABS(F2)>50000, ABS(G2)>0.1) -> FALSE
A3: Revenue | B3: 4100 | C3: Professional Services Revenue | D3: =SUMIFS(Budget!$F:$F,Budget!$A:$A,Summary!$B$1,Budget!$B:$B,Dept_Detail!$A3,Budget!$D:$D,Dept_Detail!$C3) -> 790000 | E3: =SUMIFS(GL_Actuals!$F:$F,GL_Actuals!$A:$A,Summary!$B$1,GL_Actuals!$B:$B,$A3,GL_Actuals!$D:$D,Dept_Detail!$C3) -> 561400 | F3: =E3-D3 -> -228600 | G3: =IFERROR(F3/D3,0) -> -0.28936709 | H3: =IF($A3="Revenue", IF(F3>=0,"F","U"),IF(F3<=0,"F","U")) -> U | I3: =AND(ABS(F3)>50000, ABS(G3)>0.1) -> TRUE
A4: Cost of Revenue | B4: 5000 | C4: Hosting & Infrastructure | D4: =SUMIFS(Budget!$F:$F,Budget!$A:$A,Summary!$B$1,Budget!$B:$B,Dept_Detail!$A4,Budget!$D:$D,Dept_Detail!$C4) -> 958285.9 | E4: =SUMIFS(GL_Actuals!$F:$F,GL_Actuals!$A:$A,Summary!$B$1,GL_Actuals!$B:$B,$A4,GL_Actuals!$D:$D,Dept_Detail!$C4) -> 1123443.1 | F4: =E4-D4 -> 165157.15 | G4: =IFERROR(F4/D4,0) -> 0.17234643 | H4: =IF($A4="Revenue", IF(F4>=0,"F","U"),IF(F4<=0,"F","U")) -> U | I4: =AND(ABS(F4)>50000, ABS(G4)>0.1) -> TRUE
A5: Cost of Revenue | B5: 5300 | C5: Third-Party Software Licenses | D5: =SUMIFS(Budget!$F:$F,Budget!$A:$A,Summary!$B$1,Budget!$B:$B,Dept_Detail!$A5,Budget!$D:$D,Dept_Detail!$C5) -> 183000 | E5: =SUMIFS(GL_Actuals!$F:$F,GL_Actuals!$A:$A,Summary!$B$1,GL_Actuals!$B:$B,$A5,GL_Actuals!$D:$D,Dept_Detail!$C5) -> 182464.7 | F5: =E5-D5 -> -535.3 | G5: =IFERROR(F5/D5,0) -> -0.0029251366 | H5: =IF($A5="Revenue", IF(F5>=0,"F","U"),IF(F5<=0,"F","U")) -> F | I5: =AND(ABS(F5)>50000, ABS(G5)>0.1) -> FALSE
A6: Sales | B6: 6000 | C6: Salaries & Wages | D6: =SUMIFS(Budget!$F:$F,Budget!$A:$A,Summary!$B$1,Budget!$B:$B,Dept_Detail!$A6,Budget!$D:$D,Dept_Detail!$C6) -> 897166.67 | E6: =SUMIFS(GL_Actuals!$F:$F,GL_Actuals!$A:$A,Summary!$B$1,GL_Actuals!$B:$B,$A6,GL_Actuals!$D:$D,Dept_Detail!$C6) -> 872872.36 | F6: =E6-D6 -> -24294.31 | G6: =IFERROR(F6/D6,0) -> -0.027078926 | H6: =IF($A6="Revenue", IF(F6>=0,"F","U"),IF(F6<=0,"F","U")) -> F | I6: =AND(ABS(F6)>50000, ABS(G6)>0.1) -> FALSE
A7: Sales | B7: 6010 | C7: Payroll Taxes & Benefits | D7: =SUMIFS(Budget!$F:$F,Budget!$A:$A,Summary!$B$1,Budget!$B:$B,Dept_Detail!$A7,Budget!$D:$D,Dept_Detail!$C7) -> 183919.17 | E7: =SUMIFS(GL_Actuals!$F:$F,GL_Actuals!$A:$A,Summary!$B$1,GL_Actuals!$B:$B,$A7,GL_Actuals!$D:$D,Dept_Detail!$C7) -> 177461.53 | F7: =E7-D7 -> -6457.64 | G7: =IFERROR(F7/D7,0) -> -0.035111294 | H7: =IF($A7="Revenue", IF(F7>=0,"F","U"),IF(F7<=0,"F","U")) -> F | I7: =AND(ABS(F7)>50000, ABS(G7)>0.1) -> FALSE
A8: Sales | B8: 6200 | C8: Software & Subscriptions | D8: =SUMIFS(Budget!$F:$F,Budget!$A:$A,Summary!$B$1,Budget!$B:$B,Dept_Detail!$A8,Budget!$D:$D,Dept_Detail!$C8) -> 27820 | E8: =SUMIFS(GL_Actuals!$F:$F,GL_Actuals!$A:$A,Summary!$B$1,GL_Actuals!$B:$B,$A8,GL_Actuals!$D:$D,Dept_Detail!$C8) -> 25514.69 | F8: =E8-D8 -> -2305.31 | G8: =IFERROR(F8/D8,0) -> -0.082865205 | H8: =IF($A8="Revenue", IF(F8>=0,"F","U"),IF(F8<=0,"F","U")) -> F | I8: =AND(ABS(F8)>50000, ABS(G8)>0.1) -> FALSE
A9: Sales | B9: 6300 | C9: Travel & Entertainment | D9: =SUMIFS(Budget!$F:$F,Budget!$A:$A,Summary!$B$1,Budget!$B:$B,Dept_Detail!$A9,Budget!$D:$D,Dept_Detail!$C9) -> 66340 | E9: =SUMIFS(GL_Actuals!$F:$F,GL_Actuals!$A:$A,Summary!$B$1,GL_Actuals!$B:$B,$A9,GL_Actuals!$D:$D,Dept_Detail!$C9) -> 60428.58 | F9: =E9-D9 -> -5911.42 | G9: =IFERROR(F9/D9,0) -> -0.089107929 | H9: =IF($A9="Revenue", IF(F9>=0,"F","U"),IF(F9<=0,"F","U")) -> F | I9: =AND(ABS(F9)>50000, ABS(G9)>0.1) -> FALSE
A10: Sales | B10: 6800 | C10: Recruiting | D10: =SUMIFS(Budget!$F:$F,Budget!$A:$A,Summary!$B$1,Budget!$B:$B,Dept_Detail!$A10,Budget!$D:$D,Dept_Detail!$C10) -> 17500 | E10: =SUMIFS(GL_Actuals!$F:$F,GL_Actuals!$A:$A,Summary!$B$1,GL_Actuals!$B:$B,$A10,GL_Actuals!$D:$D,Dept_Detail!$C10) -> 8323.28 | F10: =E10-D10 -> -9176.72 | G10: =IFERROR(F10/D10,0) -> -0.524384 | H10: =IF($A10="Revenue", IF(F10>=0,"F","U"),IF(F10<=0,"F","U")) -> F | I10: =AND(ABS(F10)>50000, ABS(G10)>0.1) -> FALSE
A11: Marketing | B11: 6000 | C11: Salaries & Wages | D11: =SUMIFS(Budget!$F:$F,Budget!$A:$A,Summary!$B$1,Budget!$B:$B,Dept_Detail!$A11,Budget!$D:$D,Dept_Detail!$C11) -> 307333.33 | E11: =SUMIFS(GL_Actuals!$F:$F,GL_Actuals!$A:$A,Summary!$B$1,GL_Actuals!$B:$B,$A11,GL_Actuals!$D:$D,Dept_Detail!$C11) -> 298785.36 | F11: =E11-D11 -> -8547.97 | G11: =IFERROR(F11/D11,0) -> -0.027813352 | H11: =IF($A11="Revenue", IF(F11>=0,"F","U"),IF(F11<=0,"F","U")) -> F | I11: =AND(ABS(F11)>50000, ABS(G11)>0.1) -> FALSE
A12: Marketing | B12: 6010 | C12: Payroll Taxes & Benefits | D12: =SUMIFS(Budget!$F:$F,Budget!$A:$A,Summary!$B$1,Budget!$B:$B,Dept_Detail!$A12,Budget!$D:$D,Dept_Detail!$C12) -> 63003.33 | E12: =SUMIFS(GL_Actuals!$F:$F,GL_Actuals!$A:$A,Summary!$B$1,GL_Actuals!$B:$B,$A12,GL_Actuals!$D:$D,Dept_Detail!$C12) -> 60672.33 | F12: =E12-D12 -> -2331 | G12: =IFERROR(F12/D12,0) -> -0.036998044 | H12: =IF($A12="Revenue", IF(F12>=0,"F","U"),IF(F12<=0,"F","U")) -> F | I12: =AND(ABS(F12)>50000, ABS(G12)>0.1) -> FALSE
A13: Marketing | B13: 6200 | C13: Software & Subscriptions | D13: =SUMIFS(Budget!$F:$F,Budget!$A:$A,Summary!$B$1,Budget!$B:$B,Dept_Detail!$A13,Budget!$D:$D,Dept_Detail!$C13) -> 8320 | E13: =SUMIFS(GL_Actuals!$F:$F,GL_Actuals!$A:$A,Summary!$B$1,GL_Actuals!$B:$B,$A13,GL_Actuals!$D:$D,Dept_Detail!$C13) -> 9208.12 | F13: =E13-D13 -> 888.12 | G13: =IFERROR(F13/D13,0) -> 0.10674519 | H13: =IF($A13="Revenue", IF(F13>=0,"F","U"),IF(F13<=0,"F","U")) -> U | I13: =AND(ABS(F13)>50000, ABS(G13)>0.1) -> FALSE
... A49: G&A | B49: 6700 | C49: Depreciation & Amortization | D49: =SUMIFS(Budget!$F:$F,Budget!$A:$A,Summary!$B$1,Budget!$B:$B,Dept_Detail!$A49,Budget!$D:$D,Dept_Detail!$C49) -> 151500 | E49: =SUMIFS(GL_Actuals!$F:$F,GL_Actuals!$A:$A,Summary!$B$1,GL_Actuals!$B:$B,$A49,GL_Actuals!$D:$D,Dept_Detail!$C49) -> 151500 | F49: =E49-D49 -> 0 | G49: =IFERROR(F49/D49,0) -> 0 | H49: =IF($A49="Revenue", IF(F49>=0,"F","U"),IF(F49<=0,"F","U")) -> F | I49: =AND(ABS(F49)>50000, ABS(G49)>0.1) -> FALSE
D51: Check | E51: =SUM(E2:E49)-SUMIFS(GL_Actuals!$F:$F,GL_Actuals!$A:$A,Summary!$B$1) -> 0
A53: Driver | B53: $ Var | C53: What happened | D53: Tag | E53: Q4 Impact
A54: Professional Services Revenue | B54: -228600 | C54: Two implementation milestones slipped on the customer side: Atlas Manufacturing UAT (SSO config delay) and Pinecrest Health go-live (customer data not ready). ~$220K of revenue not yet recognized | D54: Timing | E54: Reverses as favorable when milestones hit: Atlas in Oct, Pinecrest in Nov. Risk: both depend on the customer, so further slippage pushes revenue further; Pinecrest is the bigger risk
A55: Hosting & Infrastructure | B55: 165157.15 | C55: Frankfurt dual-run during customer migration $96.4K (Aug–Oct); Cirrovane reserved instances lapsed 8/31, on-demand premium $44.8K; ~$24K underlying creep (gap grew ~$30K Jan to ~$56K Jul, partly offset by Halvorsen exit) | D55: Dual-run: One-time · Lapse: Run-rate until renewed · Creep: Run-rate | E55: $192K–$446K U. Dual-run $96K (Oct only) + lapse $0–$134K + creep $96K–$216K. Action: renew Cirrovane reserved instances now (saves ~$45K/mo); owner: Engineering/IT lead + Procurement
A56: Recruiting | B56: 58320.21 | C56: Agency fees to Hollis Talent Partners for 3 Sr. Engineer hires (20% of $342.5K combined base, $68.5K); recruiting spend climbing since Jul as hiring picks up | D56: One-time per hire; recurs while hiring continues (19 open reqs) | E56: More agency fees likely (~$23K per Sr. hire) vs only $57K budgeted Oct-Dec. The 3 new hires add ~$28.5K/mo (~$86K Q4) plus taxes/benefits. Budgeted, so it shrinks the $1.35M R&D cushion rather than going over plan
A57: Sales Commissions | B57: 244179.94 | C57: $130K volume (bookings +$1.19M at 11%) + $114K Q3 accelerator true-up | D57: Volume / One-Time | E57: No accelerator Oct-Nov; Dec true-up likely if Q4 beats plan (~$255K extra commissions at Q3's pace, about half accelerator); plan has $0 for accelerators
A58: Events & Conferences | B58: 337700 | C58: CloudConnect (Sep 22-24, $318K) was budgeted for October; it ran ~$47K under its own plan | D58: Timing | E58: Reverses in Oct: ~$365K F. Reforecast Oct Events at ~$55K, not $420K
A59: Legal Fees | B59: 168034.27 | C59: Whitford & Lane litigation fees for the Brightpath contract dispute, $176K; settled 9/26. Routine counsel $37K, under budget | D59: One-time | E59: None expected. Case is settled, so legal returns to ~$45K/mo plan. (Confirm with Legal that no settlement payment or final invoices are still to come)
A60: Subscription Revenue (below threshold) | B60: -73736.67 | C60: Halvorsen Freight terminated 9/1, $1.4M ARR | D60: Run-Rate | E60: ~$350K Q4 revenue loss
A61: R&D Contractors (below threshold) | B61: =F42 -> 36020.43 | C61: Brightline Dev Studio contract engineers covering open R&D reqs ($39.6K); remainder is ongoing contractors in line with plan | D61: Run-rate while reqs stay open | E61: Offsets part of the R&D salary underspend, so the true R&D cushion is smaller than salaries alone suggest; drops away as roles fill
